[2023-12-27T16:53:27.963+0000] {taskinstance.py:1103} INFO - Dependencies all met for dep_context=non-requeueable deps ti=<TaskInstance: modeling_dag.insert_to_db manual__2023-12-27T16:53:21.038863+00:00 [queued]>
[2023-12-27T16:53:27.969+0000] {taskinstance.py:1103} INFO - Dependencies all met for dep_context=requeueable deps ti=<TaskInstance: modeling_dag.insert_to_db manual__2023-12-27T16:53:21.038863+00:00 [queued]>
[2023-12-27T16:53:27.969+0000] {taskinstance.py:1308} INFO - Starting attempt 1 of 1
[2023-12-27T16:53:27.979+0000] {taskinstance.py:1327} INFO - Executing <Task(PythonOperator): insert_to_db> on 2023-12-27 16:53:21.038863+00:00
[2023-12-27T16:53:27.985+0000] {standard_task_runner.py:57} INFO - Started process 4524 to run task
[2023-12-27T16:53:27.987+0000] {standard_task_runner.py:84} INFO - Running: ['***', 'tasks', 'run', 'modeling_dag', 'insert_to_db', 'manual__2023-12-27T16:53:21.038863+00:00', '--job-id', '456', '--raw', '--subdir', 'DAGS_FOLDER/modeling.py', '--cfg-path', '/tmp/tmpod55t_k9']
[2023-12-27T16:53:27.989+0000] {standard_task_runner.py:85} INFO - Job 456: Subtask insert_to_db
[2023-12-27T16:53:28.021+0000] {task_command.py:410} INFO - Running <TaskInstance: modeling_dag.insert_to_db manual__2023-12-27T16:53:21.038863+00:00 [running]> on host c56b1de7f6cf
[2023-12-27T16:53:28.080+0000] {taskinstance.py:1547} INFO - Exporting env vars: AIRFLOW_CTX_DAG_OWNER='***' AIRFLOW_CTX_DAG_ID='modeling_dag' AIRFLOW_CTX_TASK_ID='insert_to_db' AIRFLOW_CTX_EXECUTION_DATE='2023-12-27T16:53:21.038863+00:00' AIRFLOW_CTX_TRY_NUMBER='1' AIRFLOW_CTX_DAG_RUN_ID='manual__2023-12-27T16:53:21.038863+00:00'
[2023-12-27T16:53:28.108+0000] {taskinstance.py:1824} ERROR - Task failed with exception
Traceback (most recent call last):
  File "/home/airflow/.local/lib/python3.7/site-packages/airflow/operators/python.py", line 181, in execute
    return_value = self.execute_callable()
  File "/home/airflow/.local/lib/python3.7/site-packages/airflow/operators/python.py", line 198, in execute_callable
    return self.python_callable(*self.op_args, **self.op_kwargs)
  File "/opt/airflow/dags/modeling.py", line 104, in insert_to_db
    cursor.execute(insert_query, (current_time, float(new_pred_pacs[0]), int(new_pred_cluster[0]),float(ntu_pred)))
psycopg2.errors.UndefinedFunction: operator does not exist: text == double precision
LINE 6:     WHERE "logTime" == 'NaN'::float;
                            ^
HINT:  No operator matches the given name and argument types. You might need to add explicit type casts.

[2023-12-27T16:53:28.115+0000] {taskinstance.py:1350} INFO - Marking task as FAILED. dag_id=modeling_dag, task_id=insert_to_db, execution_date=20231227T165321, start_date=20231227T165327, end_date=20231227T165328
[2023-12-27T16:53:28.125+0000] {standard_task_runner.py:109} ERROR - Failed to execute job 456 for task insert_to_db (operator does not exist: text == double precision
LINE 6:     WHERE "logTime" == 'NaN'::float;
                            ^
HINT:  No operator matches the given name and argument types. You might need to add explicit type casts.
; 4524)
[2023-12-27T16:53:28.159+0000] {local_task_job_runner.py:225} INFO - Task exited with return code 1
[2023-12-27T16:53:28.177+0000] {taskinstance.py:2653} INFO - 0 downstream tasks scheduled from follow-on schedule check
