[2023-12-20T02:54:29.991+0000] {taskinstance.py:1103} INFO - Dependencies all met for dep_context=non-requeueable deps ti=<TaskInstance: combined_dag.apply_last_update_time_to_new_data manual__2023-12-20T02:54:14.778414+00:00 [queued]>
[2023-12-20T02:54:29.998+0000] {taskinstance.py:1103} INFO - Dependencies all met for dep_context=requeueable deps ti=<TaskInstance: combined_dag.apply_last_update_time_to_new_data manual__2023-12-20T02:54:14.778414+00:00 [queued]>
[2023-12-20T02:54:29.998+0000] {taskinstance.py:1308} INFO - Starting attempt 1 of 1
[2023-12-20T02:54:30.008+0000] {taskinstance.py:1327} INFO - Executing <Task(PythonOperator): apply_last_update_time_to_new_data> on 2023-12-20 02:54:14.778414+00:00
[2023-12-20T02:54:30.015+0000] {standard_task_runner.py:57} INFO - Started process 1898 to run task
[2023-12-20T02:54:30.017+0000] {standard_task_runner.py:84} INFO - Running: ['***', 'tasks', 'run', 'combined_dag', 'apply_last_update_time_to_new_data', 'manual__2023-12-20T02:54:14.778414+00:00', '--job-id', '39', '--raw', '--subdir', 'DAGS_FOLDER/combined_dag(real).py', '--cfg-path', '/tmp/tmpcij401x3']
[2023-12-20T02:54:30.019+0000] {standard_task_runner.py:85} INFO - Job 39: Subtask apply_last_update_time_to_new_data
[2023-12-20T02:54:30.051+0000] {task_command.py:410} INFO - Running <TaskInstance: combined_dag.apply_last_update_time_to_new_data manual__2023-12-20T02:54:14.778414+00:00 [running]> on host b045abe315e4
[2023-12-20T02:54:30.106+0000] {taskinstance.py:1547} INFO - Exporting env vars: AIRFLOW_CTX_DAG_OWNER='***' AIRFLOW_CTX_DAG_ID='combined_dag' AIRFLOW_CTX_TASK_ID='apply_last_update_time_to_new_data' AIRFLOW_CTX_EXECUTION_DATE='2023-12-20T02:54:14.778414+00:00' AIRFLOW_CTX_TRY_NUMBER='1' AIRFLOW_CTX_DAG_RUN_ID='manual__2023-12-20T02:54:14.778414+00:00'
[2023-12-20T02:54:30.158+0000] {taskinstance.py:1824} ERROR - Task failed with exception
Traceback (most recent call last):
  File "/home/airflow/.local/lib/python3.7/site-packages/airflow/operators/python.py", line 181, in execute
    return_value = self.execute_callable()
  File "/home/airflow/.local/lib/python3.7/site-packages/airflow/operators/python.py", line 198, in execute_callable
    return self.python_callable(*self.op_args, **self.op_kwargs)
  File "/opt/airflow/dags/combined_dag(real).py", line 138, in replace_missing_update_time
    prev_value = cursor.fetchone()[0]
TypeError: 'NoneType' object is not subscriptable
[2023-12-20T02:54:30.165+0000] {taskinstance.py:1350} INFO - Marking task as FAILED. dag_id=combined_dag, task_id=apply_last_update_time_to_new_data, execution_date=20231220T025414, start_date=20231220T025429, end_date=20231220T025430
[2023-12-20T02:54:30.173+0000] {standard_task_runner.py:109} ERROR - Failed to execute job 39 for task apply_last_update_time_to_new_data ('NoneType' object is not subscriptable; 1898)
[2023-12-20T02:54:30.189+0000] {local_task_job_runner.py:225} INFO - Task exited with return code 1
[2023-12-20T02:54:30.202+0000] {taskinstance.py:2653} INFO - 0 downstream tasks scheduled from follow-on schedule check
