[2023-12-27T17:26:59.653+0000] {taskinstance.py:1103} INFO - Dependencies all met for dep_context=non-requeueable deps ti=<TaskInstance: combined_dag.apply_last_update_time_to_new_data manual__2023-12-27T17:26:48.643083+00:00 [queued]>
[2023-12-27T17:26:59.662+0000] {taskinstance.py:1103} INFO - Dependencies all met for dep_context=requeueable deps ti=<TaskInstance: combined_dag.apply_last_update_time_to_new_data manual__2023-12-27T17:26:48.643083+00:00 [queued]>
[2023-12-27T17:26:59.663+0000] {taskinstance.py:1308} INFO - Starting attempt 1 of 1
[2023-12-27T17:26:59.677+0000] {taskinstance.py:1327} INFO - Executing <Task(PythonOperator): apply_last_update_time_to_new_data> on 2023-12-27 17:26:48.643083+00:00
[2023-12-27T17:26:59.685+0000] {standard_task_runner.py:57} INFO - Started process 189 to run task
[2023-12-27T17:26:59.687+0000] {standard_task_runner.py:84} INFO - Running: ['***', 'tasks', 'run', 'combined_dag', 'apply_last_update_time_to_new_data', 'manual__2023-12-27T17:26:48.643083+00:00', '--job-id', '518', '--raw', '--subdir', 'DAGS_FOLDER/combined_dag(real).py', '--cfg-path', '/tmp/tmppvhkn3dm']
[2023-12-27T17:26:59.689+0000] {standard_task_runner.py:85} INFO - Job 518: Subtask apply_last_update_time_to_new_data
[2023-12-27T17:26:59.727+0000] {task_command.py:410} INFO - Running <TaskInstance: combined_dag.apply_last_update_time_to_new_data manual__2023-12-27T17:26:48.643083+00:00 [running]> on host c56b1de7f6cf
[2023-12-27T17:26:59.786+0000] {taskinstance.py:1547} INFO - Exporting env vars: AIRFLOW_CTX_DAG_OWNER='***' AIRFLOW_CTX_DAG_ID='combined_dag' AIRFLOW_CTX_TASK_ID='apply_last_update_time_to_new_data' AIRFLOW_CTX_EXECUTION_DATE='2023-12-27T17:26:48.643083+00:00' AIRFLOW_CTX_TRY_NUMBER='1' AIRFLOW_CTX_DAG_RUN_ID='manual__2023-12-27T17:26:48.643083+00:00'
[2023-12-27T17:26:59.826+0000] {taskinstance.py:1824} ERROR - Task failed with exception
Traceback (most recent call last):
  File "/home/airflow/.local/lib/python3.7/site-packages/airflow/operators/python.py", line 181, in execute
    return_value = self.execute_callable()
  File "/home/airflow/.local/lib/python3.7/site-packages/airflow/operators/python.py", line 198, in execute_callable
    return self.python_callable(*self.op_args, **self.op_kwargs)
  File "/opt/airflow/dags/combined_dag(real).py", line 138, in replace_missing_update_time
    prev_value = cursor.fetchone()[0]
TypeError: 'NoneType' object is not subscriptable
[2023-12-27T17:26:59.832+0000] {taskinstance.py:1350} INFO - Marking task as FAILED. dag_id=combined_dag, task_id=apply_last_update_time_to_new_data, execution_date=20231227T172648, start_date=20231227T172659, end_date=20231227T172659
[2023-12-27T17:26:59.842+0000] {standard_task_runner.py:109} ERROR - Failed to execute job 518 for task apply_last_update_time_to_new_data ('NoneType' object is not subscriptable; 189)
[2023-12-27T17:26:59.859+0000] {local_task_job_runner.py:225} INFO - Task exited with return code 1
[2023-12-27T17:26:59.871+0000] {taskinstance.py:2653} INFO - 0 downstream tasks scheduled from follow-on schedule check
