[2023-12-27T17:20:23.814+0000] {taskinstance.py:1103} INFO - Dependencies all met for dep_context=non-requeueable deps ti=<TaskInstance: combined_dag.generate_random_data_task manual__2023-12-27T17:20:21.547608+00:00 [queued]>
[2023-12-27T17:20:23.825+0000] {taskinstance.py:1103} INFO - Dependencies all met for dep_context=requeueable deps ti=<TaskInstance: combined_dag.generate_random_data_task manual__2023-12-27T17:20:21.547608+00:00 [queued]>
[2023-12-27T17:20:23.825+0000] {taskinstance.py:1308} INFO - Starting attempt 1 of 1
[2023-12-27T17:20:23.850+0000] {taskinstance.py:1327} INFO - Executing <Task(PythonOperator): generate_random_data_task> on 2023-12-27 17:20:21.547608+00:00
[2023-12-27T17:20:23.861+0000] {standard_task_runner.py:57} INFO - Started process 7086 to run task
[2023-12-27T17:20:23.866+0000] {standard_task_runner.py:84} INFO - Running: ['***', 'tasks', 'run', 'combined_dag', 'generate_random_data_task', 'manual__2023-12-27T17:20:21.547608+00:00', '--job-id', '504', '--raw', '--subdir', 'DAGS_FOLDER/combined_dag(real).py', '--cfg-path', '/tmp/tmpkjpj3reb']
[2023-12-27T17:20:23.869+0000] {standard_task_runner.py:85} INFO - Job 504: Subtask generate_random_data_task
[2023-12-27T17:20:23.927+0000] {task_command.py:410} INFO - Running <TaskInstance: combined_dag.generate_random_data_task manual__2023-12-27T17:20:21.547608+00:00 [running]> on host c56b1de7f6cf
[2023-12-27T17:20:24.016+0000] {taskinstance.py:1547} INFO - Exporting env vars: AIRFLOW_CTX_DAG_OWNER='***' AIRFLOW_CTX_DAG_ID='combined_dag' AIRFLOW_CTX_TASK_ID='generate_random_data_task' AIRFLOW_CTX_EXECUTION_DATE='2023-12-27T17:20:21.547608+00:00' AIRFLOW_CTX_TRY_NUMBER='1' AIRFLOW_CTX_DAG_RUN_ID='manual__2023-12-27T17:20:21.547608+00:00'
[2023-12-27T17:20:45.069+0000] {taskinstance.py:1824} ERROR - Task failed with exception
Traceback (most recent call last):
  File "/home/airflow/.local/lib/python3.7/site-packages/airflow/operators/python.py", line 181, in execute
    return_value = self.execute_callable()
  File "/home/airflow/.local/lib/python3.7/site-packages/airflow/operators/python.py", line 198, in execute_callable
    return self.python_callable(*self.op_args, **self.op_kwargs)
  File "/opt/airflow/dags/combined_dag(real).py", line 21, in generate_random_data
    password="airflow"
  File "/home/airflow/.local/lib/python3.7/site-packages/psycopg2/__init__.py", line 122, in connect
    conn = _connect(dsn, connection_factory=connection_factory, **kwasync)
psycopg2.OperationalError: connection to server at "192.168.35.31", port 5432 failed: Connection refused
	Is the server running on that host and accepting TCP/IP connections?

[2023-12-27T17:20:45.076+0000] {taskinstance.py:1350} INFO - Marking task as FAILED. dag_id=combined_dag, task_id=generate_random_data_task, execution_date=20231227T172021, start_date=20231227T172023, end_date=20231227T172045
[2023-12-27T17:20:45.087+0000] {standard_task_runner.py:109} ERROR - Failed to execute job 504 for task generate_random_data_task (connection to server at "192.168.35.31", port 5432 failed: Connection refused
	Is the server running on that host and accepting TCP/IP connections?
; 7086)
[2023-12-27T17:20:45.114+0000] {local_task_job_runner.py:225} INFO - Task exited with return code 1
[2023-12-27T17:20:45.130+0000] {taskinstance.py:2653} INFO - 0 downstream tasks scheduled from follow-on schedule check
