[2024-01-03T11:46:10.288+0000] {taskinstance.py:1103} INFO - Dependencies all met for dep_context=non-requeueable deps ti=<TaskInstance: modeling_dag.insert_task scheduled__2024-01-03T11:45:00+00:00 [queued]>
[2024-01-03T11:46:10.295+0000] {taskinstance.py:1103} INFO - Dependencies all met for dep_context=requeueable deps ti=<TaskInstance: modeling_dag.insert_task scheduled__2024-01-03T11:45:00+00:00 [queued]>
[2024-01-03T11:46:10.295+0000] {taskinstance.py:1308} INFO - Starting attempt 1 of 1
[2024-01-03T11:46:10.305+0000] {taskinstance.py:1327} INFO - Executing <Task(PythonOperator): insert_task> on 2024-01-03 11:45:00+00:00
[2024-01-03T11:46:10.310+0000] {standard_task_runner.py:57} INFO - Started process 2024 to run task
[2024-01-03T11:46:10.313+0000] {standard_task_runner.py:84} INFO - Running: ['***', 'tasks', 'run', 'modeling_dag', 'insert_task', 'scheduled__2024-01-03T11:45:00+00:00', '--job-id', '61', '--raw', '--subdir', 'DAGS_FOLDER/modeling.py', '--cfg-path', '/tmp/tmp5zoa6g75']
[2024-01-03T11:46:10.314+0000] {standard_task_runner.py:85} INFO - Job 61: Subtask insert_task
[2024-01-03T11:46:10.345+0000] {task_command.py:410} INFO - Running <TaskInstance: modeling_dag.insert_task scheduled__2024-01-03T11:45:00+00:00 [running]> on host 93456042b127
[2024-01-03T11:46:10.397+0000] {taskinstance.py:1547} INFO - Exporting env vars: AIRFLOW_CTX_DAG_OWNER='***' AIRFLOW_CTX_DAG_ID='modeling_dag' AIRFLOW_CTX_TASK_ID='insert_task' AIRFLOW_CTX_EXECUTION_DATE='2024-01-03T11:45:00+00:00' AIRFLOW_CTX_TRY_NUMBER='1' AIRFLOW_CTX_DAG_RUN_ID='scheduled__2024-01-03T11:45:00+00:00'
[2024-01-03T11:46:10.417+0000] {logging_mixin.py:150} INFO - [15.73407, 6.57171, 24.79203, 366.25779, 53.127990000000004, 2582.4375]
[2024-01-03T11:46:10.422+0000] {taskinstance.py:1824} ERROR - Task failed with exception
Traceback (most recent call last):
  File "/home/airflow/.local/lib/python3.7/site-packages/airflow/operators/python.py", line 181, in execute
    return_value = self.execute_callable()
  File "/home/airflow/.local/lib/python3.7/site-packages/airflow/operators/python.py", line 198, in execute_callable
    return self.python_callable(*self.op_args, **self.op_kwargs)
  File "/opt/airflow/dags/modeling.py", line 131, in insert_to_db
    cursor.execute(insert_query, (current_time, new_data[0][0], new_data[0][1], new_data[0][2], new_data[0][3], new_data[0][4], float(new_pred_pacs[0]), int(new_pred_cluster[0]), new_data[0][5], float(ntu_pred)))
TypeError: 'float' object is not subscriptable
[2024-01-03T11:46:10.428+0000] {taskinstance.py:1350} INFO - Marking task as FAILED. dag_id=modeling_dag, task_id=insert_task, execution_date=20240103T114500, start_date=20240103T114610, end_date=20240103T114610
[2024-01-03T11:46:10.435+0000] {standard_task_runner.py:109} ERROR - Failed to execute job 61 for task insert_task ('float' object is not subscriptable; 2024)
[2024-01-03T11:46:10.444+0000] {local_task_job_runner.py:225} INFO - Task exited with return code 1
[2024-01-03T11:46:10.456+0000] {taskinstance.py:2653} INFO - 0 downstream tasks scheduled from follow-on schedule check
