[2024-01-09T05:44:24.145+0000] {taskinstance.py:1103} INFO - Dependencies all met for dep_context=non-requeueable deps ti=<TaskInstance: modeling_dag.load_modeling scheduled__2024-01-09T05:43:00+00:00 [queued]>
[2024-01-09T05:44:24.152+0000] {taskinstance.py:1103} INFO - Dependencies all met for dep_context=requeueable deps ti=<TaskInstance: modeling_dag.load_modeling scheduled__2024-01-09T05:43:00+00:00 [queued]>
[2024-01-09T05:44:24.152+0000] {taskinstance.py:1308} INFO - Starting attempt 1 of 1
[2024-01-09T05:44:24.162+0000] {taskinstance.py:1327} INFO - Executing <Task(PythonOperator): load_modeling> on 2024-01-09 05:43:00+00:00
[2024-01-09T05:44:24.167+0000] {standard_task_runner.py:57} INFO - Started process 1190 to run task
[2024-01-09T05:44:24.170+0000] {standard_task_runner.py:84} INFO - Running: ['***', 'tasks', 'run', 'modeling_dag', 'load_modeling', 'scheduled__2024-01-09T05:43:00+00:00', '--job-id', '222', '--raw', '--subdir', 'DAGS_FOLDER/modeling.py', '--cfg-path', '/tmp/tmpx1nm5idv']
[2024-01-09T05:44:24.172+0000] {standard_task_runner.py:85} INFO - Job 222: Subtask load_modeling
[2024-01-09T05:44:24.200+0000] {task_command.py:410} INFO - Running <TaskInstance: modeling_dag.load_modeling scheduled__2024-01-09T05:43:00+00:00 [running]> on host 93456042b127
[2024-01-09T05:44:24.261+0000] {taskinstance.py:1547} INFO - Exporting env vars: AIRFLOW_CTX_DAG_OWNER='***' AIRFLOW_CTX_DAG_ID='modeling_dag' AIRFLOW_CTX_TASK_ID='load_modeling' AIRFLOW_CTX_EXECUTION_DATE='2024-01-09T05:43:00+00:00' AIRFLOW_CTX_TRY_NUMBER='1' AIRFLOW_CTX_DAG_RUN_ID='scheduled__2024-01-09T05:43:00+00:00'
[2024-01-09T05:44:24.790+0000] {taskinstance.py:1824} ERROR - Task failed with exception
Traceback (most recent call last):
  File "/home/airflow/.local/lib/python3.7/site-packages/airflow/operators/python.py", line 181, in execute
    return_value = self.execute_callable()
  File "/home/airflow/.local/lib/python3.7/site-packages/airflow/operators/python.py", line 198, in execute_callable
    return self.python_callable(*self.op_args, **self.op_kwargs)
  File "/opt/airflow/dags/modeling.py", line 102, in load_modeling
    new_pred_cluster = cl_model.predict([new_data[0][0:5]])
TypeError: 'NoneType' object is not subscriptable
[2024-01-09T05:44:24.796+0000] {taskinstance.py:1350} INFO - Marking task as FAILED. dag_id=modeling_dag, task_id=load_modeling, execution_date=20240109T054300, start_date=20240109T054424, end_date=20240109T054424
[2024-01-09T05:44:24.804+0000] {standard_task_runner.py:109} ERROR - Failed to execute job 222 for task load_modeling ('NoneType' object is not subscriptable; 1190)
[2024-01-09T05:44:24.864+0000] {local_task_job_runner.py:225} INFO - Task exited with return code 1
[2024-01-09T05:44:24.889+0000] {taskinstance.py:2653} INFO - 0 downstream tasks scheduled from follow-on schedule check
