[2023-12-27T16:38:12.504+0000] {taskinstance.py:1103} INFO - Dependencies all met for dep_context=non-requeueable deps ti=<TaskInstance: modeling_dag.insert_to_db manual__2023-12-27T16:38:06.023412+00:00 [queued]>
[2023-12-27T16:38:12.513+0000] {taskinstance.py:1103} INFO - Dependencies all met for dep_context=requeueable deps ti=<TaskInstance: modeling_dag.insert_to_db manual__2023-12-27T16:38:06.023412+00:00 [queued]>
[2023-12-27T16:38:12.513+0000] {taskinstance.py:1308} INFO - Starting attempt 1 of 1
[2023-12-27T16:38:12.527+0000] {taskinstance.py:1327} INFO - Executing <Task(PythonOperator): insert_to_db> on 2023-12-27 16:38:06.023412+00:00
[2023-12-27T16:38:12.534+0000] {standard_task_runner.py:57} INFO - Started process 3033 to run task
[2023-12-27T16:38:12.536+0000] {standard_task_runner.py:84} INFO - Running: ['***', 'tasks', 'run', 'modeling_dag', 'insert_to_db', 'manual__2023-12-27T16:38:06.023412+00:00', '--job-id', '405', '--raw', '--subdir', 'DAGS_FOLDER/modeling.py', '--cfg-path', '/tmp/tmpkor7a1b3']
[2023-12-27T16:38:12.538+0000] {standard_task_runner.py:85} INFO - Job 405: Subtask insert_to_db
[2023-12-27T16:38:12.570+0000] {task_command.py:410} INFO - Running <TaskInstance: modeling_dag.insert_to_db manual__2023-12-27T16:38:06.023412+00:00 [running]> on host c56b1de7f6cf
[2023-12-27T16:38:12.624+0000] {taskinstance.py:1547} INFO - Exporting env vars: AIRFLOW_CTX_DAG_OWNER='***' AIRFLOW_CTX_DAG_ID='modeling_dag' AIRFLOW_CTX_TASK_ID='insert_to_db' AIRFLOW_CTX_EXECUTION_DATE='2023-12-27T16:38:06.023412+00:00' AIRFLOW_CTX_TRY_NUMBER='1' AIRFLOW_CTX_DAG_RUN_ID='manual__2023-12-27T16:38:06.023412+00:00'
[2023-12-27T16:38:12.632+0000] {taskinstance.py:1824} ERROR - Task failed with exception
Traceback (most recent call last):
  File "/home/airflow/.local/lib/python3.7/site-packages/airflow/operators/python.py", line 181, in execute
    return_value = self.execute_callable()
  File "/home/airflow/.local/lib/python3.7/site-packages/airflow/operators/python.py", line 198, in execute_callable
    return self.python_callable(*self.op_args, **self.op_kwargs)
  File "/opt/airflow/dags/modeling.py", line 128, in insert_to_db
    new_data = ti.xcom_pull(task_ids='generate_random_data_task')[0]
TypeError: 'NoneType' object is not subscriptable
[2023-12-27T16:38:12.637+0000] {taskinstance.py:1350} INFO - Marking task as FAILED. dag_id=modeling_dag, task_id=insert_to_db, execution_date=20231227T163806, start_date=20231227T163812, end_date=20231227T163812
[2023-12-27T16:38:12.645+0000] {standard_task_runner.py:109} ERROR - Failed to execute job 405 for task insert_to_db ('NoneType' object is not subscriptable; 3033)
[2023-12-27T16:38:12.668+0000] {local_task_job_runner.py:225} INFO - Task exited with return code 1
[2023-12-27T16:38:12.684+0000] {taskinstance.py:2653} INFO - 0 downstream tasks scheduled from follow-on schedule check
