[2023-12-27T16:31:31.361+0000] {taskinstance.py:1103} INFO - Dependencies all met for dep_context=non-requeueable deps ti=<TaskInstance: modeling_dag.load_modeling manual__2023-12-27T16:31:29.461458+00:00 [queued]>
[2023-12-27T16:31:31.368+0000] {taskinstance.py:1103} INFO - Dependencies all met for dep_context=requeueable deps ti=<TaskInstance: modeling_dag.load_modeling manual__2023-12-27T16:31:29.461458+00:00 [queued]>
[2023-12-27T16:31:31.368+0000] {taskinstance.py:1308} INFO - Starting attempt 1 of 1
[2023-12-27T16:31:31.378+0000] {taskinstance.py:1327} INFO - Executing <Task(PythonOperator): load_modeling> on 2023-12-27 16:31:29.461458+00:00
[2023-12-27T16:31:31.383+0000] {standard_task_runner.py:57} INFO - Started process 2416 to run task
[2023-12-27T16:31:31.386+0000] {standard_task_runner.py:84} INFO - Running: ['***', 'tasks', 'run', 'modeling_dag', 'load_modeling', 'manual__2023-12-27T16:31:29.461458+00:00', '--job-id', '399', '--raw', '--subdir', 'DAGS_FOLDER/modeling.py', '--cfg-path', '/tmp/tmpt3vzvtlw']
[2023-12-27T16:31:31.389+0000] {standard_task_runner.py:85} INFO - Job 399: Subtask load_modeling
[2023-12-27T16:31:31.423+0000] {task_command.py:410} INFO - Running <TaskInstance: modeling_dag.load_modeling manual__2023-12-27T16:31:29.461458+00:00 [running]> on host c56b1de7f6cf
[2023-12-27T16:31:31.475+0000] {taskinstance.py:1547} INFO - Exporting env vars: AIRFLOW_CTX_DAG_OWNER='***' AIRFLOW_CTX_DAG_ID='modeling_dag' AIRFLOW_CTX_TASK_ID='load_modeling' AIRFLOW_CTX_EXECUTION_DATE='2023-12-27T16:31:29.461458+00:00' AIRFLOW_CTX_TRY_NUMBER='1' AIRFLOW_CTX_DAG_RUN_ID='manual__2023-12-27T16:31:29.461458+00:00'
[2023-12-27T16:31:31.521+0000] {logging_mixin.py:150} INFO - 내용             logTime        탁도      pH  ...    원수유입유량  예측탁도  update_time
0  2023/12/28 00:56  16.63857  6.6096  ...  3285.649  None         None

[1 rows x 11 columns]
[2023-12-27T16:31:31.522+0000] {logging_mixin.py:150} INFO - 타입 <class 'pandas.core.frame.DataFrame'>
[2023-12-27T16:31:32.169+0000] {taskinstance.py:1824} ERROR - Task failed with exception
Traceback (most recent call last):
  File "/home/airflow/.local/lib/python3.7/site-packages/pandas/core/indexes/base.py", line 3361, in get_loc
    return self._engine.get_loc(casted_key)
  File "pandas/_libs/index.pyx", line 76, in pandas._libs.index.IndexEngine.get_loc
  File "pandas/_libs/index.pyx", line 108, in pandas._libs.index.IndexEngine.get_loc
  File "pandas/_libs/hashtable_class_helper.pxi", line 5198, in pandas._libs.hashtable.PyObjectHashTable.get_item
  File "pandas/_libs/hashtable_class_helper.pxi", line 5206, in pandas._libs.hashtable.PyObjectHashTable.get_item
KeyError: 0

The above exception was the direct cause of the following exception:

Traceback (most recent call last):
  File "/home/airflow/.local/lib/python3.7/site-packages/airflow/operators/python.py", line 181, in execute
    return_value = self.execute_callable()
  File "/home/airflow/.local/lib/python3.7/site-packages/airflow/operators/python.py", line 198, in execute_callable
    return self.python_callable(*self.op_args, **self.op_kwargs)
  File "/opt/airflow/dags/modeling.py", line 117, in load_modeling
    new_pred_cluster = cl_model.predict([new_data[0][0:5]])
  File "/home/airflow/.local/lib/python3.7/site-packages/pandas/core/frame.py", line 3458, in __getitem__
    indexer = self.columns.get_loc(key)
  File "/home/airflow/.local/lib/python3.7/site-packages/pandas/core/indexes/base.py", line 3363, in get_loc
    raise KeyError(key) from err
KeyError: 0
[2023-12-27T16:31:32.178+0000] {taskinstance.py:1350} INFO - Marking task as FAILED. dag_id=modeling_dag, task_id=load_modeling, execution_date=20231227T163129, start_date=20231227T163131, end_date=20231227T163132
[2023-12-27T16:31:32.189+0000] {standard_task_runner.py:109} ERROR - Failed to execute job 399 for task load_modeling (0; 2416)
[2023-12-27T16:31:32.241+0000] {local_task_job_runner.py:225} INFO - Task exited with return code 1
[2023-12-27T16:31:32.267+0000] {taskinstance.py:2653} INFO - 0 downstream tasks scheduled from follow-on schedule check
